{
 "cells": [
  {
   "cell_type": "code",
   "execution_count": 2,
   "metadata": {},
   "outputs": [
    {
     "name": "stderr",
     "output_type": "stream",
     "text": [
      "ERROR:root:Internal Python error in the inspect module.\n",
      "Below is the traceback from this internal error.\n",
      "\n"
     ]
    },
    {
     "name": "stdout",
     "output_type": "stream",
     "text": [
      "Traceback (most recent call last):\n",
      "  File \"C:\\Users\\heber\\anaconda3\\lib\\site-packages\\IPython\\core\\interactiveshell.py\", line 3331, in run_code\n",
      "    exec(code_obj, self.user_global_ns, self.user_ns)\n",
      "  File \"<ipython-input-2-23d902bbc8cf>\", line 3, in <module>\n",
      "    from tensorflow.python.keras.preprocessing.image import ImageDataGenerator\n",
      "  File \"C:\\Users\\heber\\anaconda3\\lib\\site-packages\\tensorflow_core\\python\\keras\\__init__.py\", line 27, in <module>\n",
      "    from tensorflow.python.keras import applications\n",
      "  File \"C:\\Users\\heber\\anaconda3\\lib\\site-packages\\tensorflow_core\\python\\keras\\applications\\__init__.py\", line 25, in <module>\n",
      "    from tensorflow.python.keras import engine\n",
      "  File \"C:\\Users\\heber\\anaconda3\\lib\\site-packages\\tensorflow_core\\python\\keras\\engine\\__init__.py\", line 23, in <module>\n",
      "    from tensorflow.python.keras.engine.base_layer import Layer\n",
      "  File \"C:\\Users\\heber\\anaconda3\\lib\\site-packages\\tensorflow_core\\python\\keras\\engine\\base_layer.py\", line 56, in <module>\n",
      "    from tensorflow.python.keras.saving.saved_model import layer_serialization\n",
      "  File \"C:\\Users\\heber\\anaconda3\\lib\\site-packages\\tensorflow_core\\python\\keras\\saving\\__init__.py\", line 20, in <module>\n",
      "    from tensorflow.python.keras.saving.hdf5_format import load_attributes_from_hdf5_group\n",
      "  File \"C:\\Users\\heber\\anaconda3\\lib\\site-packages\\tensorflow_core\\python\\keras\\saving\\hdf5_format.py\", line 32, in <module>\n",
      "    from tensorflow.python.keras.utils import conv_utils\n",
      "  File \"C:\\Users\\heber\\anaconda3\\lib\\site-packages\\tensorflow_core\\python\\keras\\utils\\__init__.py\", line 38, in <module>\n",
      "    from tensorflow.python.keras.utils.multi_gpu_utils import multi_gpu_model\n",
      "  File \"C:\\Users\\heber\\anaconda3\\lib\\site-packages\\tensorflow_core\\python\\keras\\utils\\multi_gpu_utils.py\", line 22, in <module>\n",
      "    from tensorflow.python.keras.engine.training import Model\n",
      "  File \"C:\\Users\\heber\\anaconda3\\lib\\site-packages\\tensorflow_core\\python\\keras\\engine\\training.py\", line 42, in <module>\n",
      "    from tensorflow.python.keras import metrics as metrics_module\n",
      "  File \"C:\\Users\\heber\\anaconda3\\lib\\site-packages\\tensorflow_core\\python\\keras\\metrics.py\", line 34, in <module>\n",
      "    from tensorflow.python.keras.engine.base_layer import Layer\n",
      "ImportError: cannot import name 'Layer' from 'tensorflow.python.keras.engine.base_layer' (C:\\Users\\heber\\anaconda3\\lib\\site-packages\\tensorflow_core\\python\\keras\\engine\\base_layer.py)\n",
      "\n",
      "During handling of the above exception, another exception occurred:\n",
      "\n",
      "Traceback (most recent call last):\n",
      "  File \"C:\\Users\\heber\\anaconda3\\lib\\site-packages\\IPython\\core\\interactiveshell.py\", line 2044, in showtraceback\n",
      "    stb = value._render_traceback_()\n",
      "AttributeError: 'ImportError' object has no attribute '_render_traceback_'\n",
      "\n",
      "During handling of the above exception, another exception occurred:\n",
      "\n",
      "Traceback (most recent call last):\n",
      "  File \"C:\\Users\\heber\\anaconda3\\lib\\site-packages\\IPython\\core\\ultratb.py\", line 1151, in get_records\n",
      "    return _fixed_getinnerframes(etb, number_of_lines_of_context, tb_offset)\n",
      "  File \"C:\\Users\\heber\\anaconda3\\lib\\site-packages\\IPython\\core\\ultratb.py\", line 319, in wrapped\n",
      "    return f(*args, **kwargs)\n",
      "  File \"C:\\Users\\heber\\anaconda3\\lib\\site-packages\\IPython\\core\\ultratb.py\", line 353, in _fixed_getinnerframes\n",
      "    records = fix_frame_records_filenames(inspect.getinnerframes(etb, context))\n",
      "  File \"C:\\Users\\heber\\anaconda3\\lib\\inspect.py\", line 1502, in getinnerframes\n",
      "    frameinfo = (tb.tb_frame,) + getframeinfo(tb, context)\n",
      "  File \"C:\\Users\\heber\\anaconda3\\lib\\inspect.py\", line 1460, in getframeinfo\n",
      "    filename = getsourcefile(frame) or getfile(frame)\n",
      "  File \"C:\\Users\\heber\\anaconda3\\lib\\inspect.py\", line 696, in getsourcefile\n",
      "    if getattr(getmodule(object, filename), '__loader__', None) is not None:\n",
      "  File \"C:\\Users\\heber\\anaconda3\\lib\\inspect.py\", line 733, in getmodule\n",
      "    if ismodule(module) and hasattr(module, '__file__'):\n",
      "  File \"C:\\Users\\heber\\anaconda3\\lib\\site-packages\\tensorflow\\__init__.py\", line 50, in __getattr__\n",
      "    module = self._load()\n",
      "  File \"C:\\Users\\heber\\anaconda3\\lib\\site-packages\\tensorflow\\__init__.py\", line 44, in _load\n",
      "    module = _importlib.import_module(self.__name__)\n",
      "  File \"C:\\Users\\heber\\anaconda3\\lib\\importlib\\__init__.py\", line 127, in import_module\n",
      "    return _bootstrap._gcd_import(name[level:], package, level)\n",
      "  File \"<frozen importlib._bootstrap>\", line 1006, in _gcd_import\n",
      "  File \"<frozen importlib._bootstrap>\", line 983, in _find_and_load\n",
      "  File \"<frozen importlib._bootstrap>\", line 953, in _find_and_load_unlocked\n",
      "  File \"<frozen importlib._bootstrap>\", line 219, in _call_with_frames_removed\n",
      "  File \"<frozen importlib._bootstrap>\", line 1006, in _gcd_import\n",
      "  File \"<frozen importlib._bootstrap>\", line 983, in _find_and_load\n",
      "  File \"<frozen importlib._bootstrap>\", line 967, in _find_and_load_unlocked\n",
      "  File \"<frozen importlib._bootstrap>\", line 677, in _load_unlocked\n",
      "  File \"<frozen importlib._bootstrap_external>\", line 728, in exec_module\n",
      "  File \"<frozen importlib._bootstrap>\", line 219, in _call_with_frames_removed\n",
      "  File \"C:\\Users\\heber\\anaconda3\\lib\\site-packages\\tensorflow_core\\__init__.py\", line 45, in <module>\n",
      "    from . _api.v2 import compat\n",
      "  File \"C:\\Users\\heber\\anaconda3\\lib\\site-packages\\tensorflow_core\\_api\\v2\\compat\\__init__.py\", line 23, in <module>\n",
      "    from . import v1\n",
      "  File \"C:\\Users\\heber\\anaconda3\\lib\\site-packages\\tensorflow_core\\_api\\v2\\compat\\v1\\__init__.py\", line 40, in <module>\n",
      "    from . import experimental\n",
      "  File \"C:\\Users\\heber\\anaconda3\\lib\\site-packages\\tensorflow_core\\_api\\v2\\compat\\v1\\experimental\\__init__.py\", line 11, in <module>\n",
      "    from tensorflow.python.ops.control_flow_v2_toggles import output_all_intermediates\n",
      "  File \"C:\\Users\\heber\\anaconda3\\lib\\site-packages\\tensorflow_core\\python\\ops\\control_flow_v2_toggles.py\", line 24, in <module>\n",
      "    from tensorflow.python.ops import control_flow_util_v2\n",
      "  File \"C:\\Users\\heber\\anaconda3\\lib\\site-packages\\tensorflow_core\\python\\ops\\control_flow_util_v2.py\", line 28, in <module>\n",
      "    from tensorflow.python.keras.engine import base_layer_utils\n",
      "  File \"C:\\Users\\heber\\anaconda3\\lib\\site-packages\\tensorflow_core\\python\\keras\\__init__.py\", line 27, in <module>\n",
      "    from tensorflow.python.keras import applications\n",
      "  File \"C:\\Users\\heber\\anaconda3\\lib\\site-packages\\tensorflow_core\\python\\keras\\applications\\__init__.py\", line 25, in <module>\n",
      "    from tensorflow.python.keras import engine\n",
      "  File \"C:\\Users\\heber\\anaconda3\\lib\\site-packages\\tensorflow_core\\python\\keras\\engine\\__init__.py\", line 23, in <module>\n",
      "    from tensorflow.python.keras.engine.base_layer import Layer\n",
      "  File \"C:\\Users\\heber\\anaconda3\\lib\\site-packages\\tensorflow_core\\python\\keras\\engine\\base_layer.py\", line 56, in <module>\n",
      "    from tensorflow.python.keras.saving.saved_model import layer_serialization\n",
      "  File \"C:\\Users\\heber\\anaconda3\\lib\\site-packages\\tensorflow_core\\python\\keras\\saving\\__init__.py\", line 20, in <module>\n",
      "    from tensorflow.python.keras.saving.hdf5_format import load_attributes_from_hdf5_group\n",
      "  File \"C:\\Users\\heber\\anaconda3\\lib\\site-packages\\tensorflow_core\\python\\keras\\saving\\hdf5_format.py\", line 32, in <module>\n",
      "    from tensorflow.python.keras.utils import conv_utils\n",
      "  File \"C:\\Users\\heber\\anaconda3\\lib\\site-packages\\tensorflow_core\\python\\keras\\utils\\__init__.py\", line 38, in <module>\n",
      "    from tensorflow.python.keras.utils.multi_gpu_utils import multi_gpu_model\n",
      "  File \"C:\\Users\\heber\\anaconda3\\lib\\site-packages\\tensorflow_core\\python\\keras\\utils\\multi_gpu_utils.py\", line 22, in <module>\n",
      "    from tensorflow.python.keras.engine.training import Model\n",
      "  File \"C:\\Users\\heber\\anaconda3\\lib\\site-packages\\tensorflow_core\\python\\keras\\engine\\training.py\", line 42, in <module>\n",
      "    from tensorflow.python.keras import metrics as metrics_module\n",
      "  File \"C:\\Users\\heber\\anaconda3\\lib\\site-packages\\tensorflow_core\\python\\keras\\metrics.py\", line 34, in <module>\n",
      "    from tensorflow.python.keras.engine.base_layer import Layer\n",
      "ImportError: cannot import name 'Layer' from 'tensorflow.python.keras.engine.base_layer' (C:\\Users\\heber\\anaconda3\\lib\\site-packages\\tensorflow_core\\python\\keras\\engine\\base_layer.py)\n"
     ]
    },
    {
     "ename": "ImportError",
     "evalue": "cannot import name 'Layer' from 'tensorflow.python.keras.engine.base_layer' (C:\\Users\\heber\\anaconda3\\lib\\site-packages\\tensorflow_core\\python\\keras\\engine\\base_layer.py)",
     "output_type": "error",
     "traceback": [
      "\u001b[1;31m---------------------------------------------------------------------------\u001b[0m"
     ]
    }
   ],
   "source": [
    "import sys\n",
    "import os\n",
    "from tensorflow.python.keras.preprocessing.image import ImageDataGenerator\n",
    "from tensorflow.python.keras import optimizers\n",
    "from tensorflow.python.keras.models import Sequential\n",
    "from tensorflow.python.keras.layers import Dropout, Flatten, Dense, Activation\n",
    "from tensorflow.python.keras.layers import  Convolution2D, MaxPooling2D\n",
    "from tensorflow.python.keras import backend as K\n",
    "from tensorflow.python.keras import applications\n"
   ]
  },
  {
   "cell_type": "code",
   "execution_count": null,
   "metadata": {},
   "outputs": [],
   "source": [
    "vgg=applications.vgg16.VGG16()"
   ]
  },
  {
   "cell_type": "code",
   "execution_count": null,
   "metadata": {},
   "outputs": [],
   "source": [
    "vgg.summary()"
   ]
  },
  {
   "cell_type": "code",
   "execution_count": null,
   "metadata": {},
   "outputs": [],
   "source": [
    "cnn=Sequential()\n",
    "for capa in vgg.layers:\n",
    "    cnn.add(capa)"
   ]
  },
  {
   "cell_type": "code",
   "execution_count": null,
   "metadata": {},
   "outputs": [],
   "source": [
    "cnn.summary()"
   ]
  },
  {
   "cell_type": "code",
   "execution_count": null,
   "metadata": {},
   "outputs": [],
   "source": [
    "cnn.pop()"
   ]
  },
  {
   "cell_type": "code",
   "execution_count": null,
   "metadata": {},
   "outputs": [],
   "source": [
    "cnn.summary()"
   ]
  },
  {
   "cell_type": "code",
   "execution_count": null,
   "metadata": {},
   "outputs": [],
   "source": [
    "for layer in cnn.layers:\n",
    "    layer.trainable=False"
   ]
  },
  {
   "cell_type": "code",
   "execution_count": null,
   "metadata": {},
   "outputs": [],
   "source": [
    "cnn.add(Dense(3,activation='softmax'))"
   ]
  },
  {
   "cell_type": "code",
   "execution_count": null,
   "metadata": {},
   "outputs": [],
   "source": [
    "cnn.summary()"
   ]
  },
  {
   "cell_type": "code",
   "execution_count": null,
   "metadata": {},
   "outputs": [],
   "source": [
    "def modelo():\n",
    "    vgg=applications.vgg16.VGG16()\n",
    "    cnn=Sequential()\n",
    "        for capa in vgg.layers:\n",
    "            cnn.add(capa)\n",
    "        cnn.layers.pop()\n",
    "        for layer in cnn.layers:\n",
    "            layer.trainable=False\n",
    "        cnn.add(Dense(3,activation='softmax'))\n",
    "    \n",
    "    return cnn"
   ]
  },
  {
   "cell_type": "code",
   "execution_count": null,
   "metadata": {},
   "outputs": [],
   "source": [
    "K.clear_session()\n",
    "\n",
    "\n",
    "\n",
    "data_entrenamiento = './data/entrenamiento'\n",
    "data_validacion = './data/validacion'\n",
    "\n",
    "\n",
    "epocas=20\n",
    "longitud, altura = 150, 150\n",
    "batch_size = 32\n",
    "pasos = 1000\n",
    "validation_steps = 300\n",
    "filtrosConv1 = 32\n",
    "filtrosConv2 = 64\n",
    "tamano_filtro1 = (3, 3)\n",
    "tamano_filtro2 = (2, 2)\n",
    "tamano_pool = (2, 2)\n",
    "clases = 3\n",
    "lr = 0.0004\n",
    "\n",
    "\n",
    "##Preparamos nuestras imagenes\n",
    "\n",
    "entrenamiento_datagen = ImageDataGenerator(\n",
    "    rescale=1. / 255,\n",
    "    shear_range=0.2,\n",
    "    zoom_range=0.2,\n",
    "    horizontal_flip=True)\n",
    "\n",
    "test_datagen = ImageDataGenerator(rescale=1. / 255)\n",
    "\n",
    "entrenamiento_generador = entrenamiento_datagen.flow_from_directory(\n",
    "    data_entrenamiento,\n",
    "    target_size=(altura, longitud),\n",
    "    batch_size=batch_size,\n",
    "    class_mode='categorical')\n",
    "\n",
    "validacion_generador = test_datagen.flow_from_directory(\n",
    "    data_validacion,\n",
    "    target_size=(altura, longitud),\n",
    "    batch_size=batch_size,\n",
    "    class_mode='categorical')\n",
    "\n",
    "##TODO ESTO ES SUSTITUIDO POR LA FUNCION QUE CREA LA RED VGG16\n",
    "'''cnn = Sequential()\n",
    "cnn.add(Convolution2D(filtrosConv1, tamano_filtro1, padding =\"same\", input_shape=(longitud, altura, 3), activation='relu'))\n",
    "cnn.add(MaxPooling2D(pool_size=tamano_pool))\n",
    "\n",
    "cnn.add(Convolution2D(filtrosConv2, tamano_filtro2, padding =\"same\"))\n",
    "cnn.add(MaxPooling2D(pool_size=tamano_pool))\n",
    "\n",
    "cnn.add(Flatten())\n",
    "cnn.add(Dense(256, activation='relu'))\n",
    "cnn.add(Dropout(0.5))\n",
    "cnn.add(Dense(clases, activation='softmax'))\n",
    "'''\n",
    "\n",
    "\n",
    "##CREAR LA RED VGG16\n",
    "\n",
    "cnn=modelo()\n",
    "\n",
    "cnn.compile(loss='categorical_crossentropy',\n",
    "            optimizer=optimizers.Adam(lr=lr),\n",
    "            metrics=['accuracy'])\n",
    "\n",
    "\n",
    "cnn.fit_generator(\n",
    "    entrenamiento_generador,\n",
    "    steps_per_epoch=pasos,\n",
    "    epochs=epocas,\n",
    "    validation_data=validacion_generador,\n",
    "    validation_steps=validation_steps)\n",
    "\n",
    "target_dir = './modelo/'\n",
    "if not os.path.exists(target_dir):\n",
    "  os.mkdir(target_dir)\n",
    "cnn.save('./modelo/modelo.h5')\n",
    "cnn.save_weights('./modelo/pesos.h5')"
   ]
  },
  {
   "cell_type": "code",
   "execution_count": null,
   "metadata": {},
   "outputs": [],
   "source": []
  }
 ],
 "metadata": {
  "kernelspec": {
   "display_name": "Python 3",
   "language": "python",
   "name": "python3"
  },
  "language_info": {
   "codemirror_mode": {
    "name": "ipython",
    "version": 3
   },
   "file_extension": ".py",
   "mimetype": "text/x-python",
   "name": "python",
   "nbconvert_exporter": "python",
   "pygments_lexer": "ipython3",
   "version": "3.7.6"
  }
 },
 "nbformat": 4,
 "nbformat_minor": 2
}
